Workbook

Sheet Data Dict
B2: Data | C2: Variable | D2: Discerption
B3: E Comm | C3: CustomerID | D3: Unique customer ID
B4: E Comm | C4: Churn | D4: Churn Flag
B5: E Comm | C5: Tenure | D5: Tenure of customer in organization
B6: E Comm | C6: PreferredLoginDevice | D6: Preferred login device of customer
B7: E Comm | C7: CityTier | D7: City tier
B8: E Comm | C8: WarehouseToHome | D8: Distance in between warehouse to home of customer
B9: E Comm | C9: PreferredPaymentMode | D9: Preferred payment method of customer
B10: E Comm | C10: Gender | D10: Gender of customer
B11: E Comm | C11: HourSpendOnApp | D11: Number of hours spend on mobile application or website
B12: E Comm | C12: NumberOfDeviceRegistered | D12: Total number of deceives is registered on particular customer
B13: E Comm | C13: PreferedOrderCat | D13: Preferred order category of customer in last month
... B22: E Comm | C22: CashbackAmount | D22: Average cashback in last month

Sheet E Comm
A1: CustomerID | B1: Churn | C1: Tenure | D1: PreferredLoginDevice | E1: CityTier | F1: WarehouseToHome | G1: PreferredPaymentMode | H1: Gender | I1: HourSpendOnApp | J1: NumberOfDeviceRegistered | K1: PreferedOrderCat | L1: SatisfactionScore | M1: MaritalStatus | N1: NumberOfAddress | O1: Complain | P1: OrderAmountHikeFromlastYear | Q1: CouponUsed | R1: OrderCount | S1: DaySinceLastOrder | T1: CashbackAmount
A2: 50001 | B2: 1 | C2: 4 | D2: Mobile Phone | E2: 3 | F2: 6 | G2: Debit Card | H2: Female | I2: 3 | J2: 3 | K2: Laptop & Accessory | L2: 2 | M2: Single | N2: 9 | O2: 1 | P2: 11 | Q2: 1 | R2: 1 | S2: 5 | T2: 159.93
A3: 50002 | B3: 1 | D3: Phone | E3: 1 | F3: 8 | G3: UPI | H3: Male | I3: 3 | J3: 4 | K3: Mobile | L3: 3 | M3: Single | N3: 7 | O3: 1 | P3: 15 | Q3: 0 | R3: 1 | S3: 0 | T3: 120.9
A4: 50003 | B4: 1 | D4: Phone | E4: 1 | F4: 30 | G4: Debit Card | H4: Male | I4: 2 | J4: 4 | K4: Mobile | L4: 3 | M4: Single | N4: 6 | O4: 1 | P4: 14 | Q4: 0 | R4: 1 | S4: 3 | T4: 120.28
A5: 50004 | B5: 1 | C5: 0 | D5: Phone | E5: 3 | F5: 15 | G5: Debit Card | H5: Male | I5: 2 | J5: 4 | K5: Laptop & Accessory | L5: 5 | M5: Single | N5: 8 | O5: 0 | P5: 23 | Q5: 0 | R5: 1 | S5: 3 | T5: 134.07
A6: 50005 | B6: 1 | C6: 0 | D6: Phone | E6: 1 | F6: 12 | G6: CC | H6: Male | J6: 3 | K6: Mobile | L6: 5 | M6: Single | N6: 3 | O6: 0 | P6: 11 | Q6: 1 | R6: 1 | S6: 3 | T6: 129.6
A7: 50006 | B7: 1 | C7: 0 | D7: Computer | E7: 1 | F7: 22 | G7: Debit Card | H7: Female | I7: 3 | J7: 5 | K7: Mobile Phone | L7: 5 | M7: Single | N7: 2 | O7: 1 | P7: 22 | Q7: 4 | R7: 6 | S7: 7 | T7: 139.19
A8: 50007 | B8: 1 | D8: Phone | E8: 3 | F8: 11 | G8: Cash on Delivery | H8: Male | I8: 2 | J8: 3 | K8: Laptop & Accessory | L8: 2 | M8: Divorced | N8: 4 | O8: 0 | P8: 14 | Q8: 0 | R8: 1 | S8: 0 | T8: 120.86
A9: 50008 | B9: 1 | D9: Phone | E9: 1 | F9: 6 | G9: CC | H9: Male | I9: 3 | J9: 3 | K9: Mobile | L9: 2 | M9: Divorced | N9: 3 | O9: 1 | P9: 16 | Q9: 2 | R9: 2 | S9: 0 | T9: 122.93
A10: 50009 | B10: 1 | C10: 13 | D10: Phone | E10: 3 | F10: 9 | G10: E wallet | H10: Male | J10: 4 | K10: Mobile | L10: 3 | M10: Divorced | N10: 2 | O10: 1 | P10: 14 | Q10: 0 | R10: 1 | S10: 2 | T10: 126.83
A11: 50010 | B11: 1 | D11: Phone | E11: 1 | F11: 31 | G11: Debit Card | H11: Male | I11: 2 | J11: 5 | K11: Mobile | L11: 3 | M11: Single | N11: 2 | O11: 0 | P11: 12 | Q11: 1 | R11: 1 | S11: 1 | T11: 122.93
A12: 50011 | B12: 1 | C12: 4 | D12: Mobile Phone | E12: 1 | F12: 18 | G12: Cash on Delivery | H12: Female | I12: 2 | J12: 3 | K12: Others | L12: 3 | M12: Divorced | N12: 2 | O12: 0 | Q12: 9 | R12: 15 | S12: 8 | T12: 295.45
A13: 50012 | B13: 1 | C13: 11 | D13: Mobile Phone | E13: 1 | F13: 6 | G13: Debit Card | H13: Male | I13: 3 | J13: 4 | K13: Fashion | L13: 3 | M13: Single | N13: 10 | O13: 1 | P13: 13 | Q13: 0 | R13: 1 | S13: 0 | T13: 153.81
A14: 50013 | B14: 1 | C14: 0 | D14: Phone | E14: 1 | F14: 11 | G14: COD | H14: Male | I14: 2 | J14: 3 | K14: Mobile | L14: 3 | M14: Single | N14: 2 | O14: 1 | P14: 13 | Q14: 2 | R14: 2 | S14: 2 | T14: 134.41
A15: 50014 | B15: 1 | C15: 0 | D15: Phone | E15: 1 | F15: 15 | G15: CC | H15: Male | I15: 3 | J15: 4 | K15: Mobile | L15: 3 | M15: Divorced | N15: 1 | O15: 1 | P15: 17 | Q15: 0 | R15: 1 | S15: 0 | T15: 133.88
A16: 50015 | B16: 1 | C16: 9 | D16: Mobile Phone | E16: 3 | F16: 15 | G16: Credit Card | H16: Male | I16: 3 | J16: 4 | K16: Fashion | L16: 2 | M16: Single | N16: 2 | O16: 0 | P16: 16 | Q16: 0 | R16: 4 | S16: 7 | T16: 196.19
A17: 50016 | B17: 1 | D17: Phone | E17: 2 | F17: 12 | G17: UPI | H17: Male | I17: 3 | J17: 3 | K17: Mobile | L17: 5 | M17: Married | N17: 5 | O17: 1 | P17: 22 | Q17: 1 | R17: 1 | S17: 2 | T17: 120.73
A18: 50017 | B18: 1 | C18: 0 | D18: Computer | E18: 1 | F18: 12 | G18: Debit Card | H18: Female | J18: 4 | K18: Mobile | L18: 2 | M18: Single | N18: 2 | O18: 1 | P18: 18 | Q18: 1 | R18: 1 | S18: 0 | T18: 129.26
A19: 50018 | B19: 1 | C19: 0 | D19: Mobile Phone | E19: 3 | F19: 11 | G19: E wallet | H19: Male | I19: 2 | J19: 4 | K19: Laptop & Accessory | L19: 3 | M19: Single | N19: 2 | O19: 1 | P19: 11 | Q19: 1 | R19: 1 | S19: 3 | T19: 157.44
A20: 50019 | B20: 1 | C20: 0 | D20: Computer | E20: 1 | F20: 13 | G20: Debit Card | H20: Male | I20: 3 | J20: 5 | K20: Laptop & Accessory | L20: 3 | M20: Single | N20: 2 | O20: 1 | P20: 24 | Q20: 1 | R20: 1 | S20: 6 | T20: 160.74
A21: 50020 | B21: 1 | C21: 19 | D21: Mobile Phone | E21: 1 | F21: 20 | G21: Debit Card | H21: Female | I21: 3 | J21: 3 | K21: Mobile Phone | L21: 4 | M21: Divorced | N21: 10 | O21: 1 | P21: 18 | Q21: 1 | R21: 4 | S21: 3 | T21: 149.63
A22: 50021 | B22: 1 | C22: 0 | D22: Mobile Phone | E22: 3 | F22: 12 | G22: Debit Card | H22: Male | I22: 3 | J22: 5 | K22: Laptop & Accessory | L22: 3 | M22: Divorced | N22: 5 | O22: 1 | P22: 18 | Q22: 6 | R22: 7 | S22: 7 | T22: 161.72
A23: 50022 | B23: 1 | C23: 20 | D23: Mobile Phone | E23: 1 | F23: 29 | G23: Credit Card | H23: Female | I23: 3 | J23: 3 | K23: Fashion | L23: 2 | M23: Divorced | N23: 2 | O23: 0 | P23: 12 | Q23: 11 | R23: 15 | S23: 6 | T23: 203.12
A24: 50023 | B24: 1 | D24: Mobile Phone | E24: 3 | F24: 28 | G24: E wallet | H24: Male | I24: 2 | J24: 3 | K24: Mobile Phone | L24: 3 | M24: Single | N24: 2 | O24: 1 | P24: 19 | Q24: 0 | R24: 1 | S24: 0 | T24: 116.75
A25: 50024 | B25: 1 | C25: 0 | D25: Phone | E25: 3 | F25: 26 | G25: Debit Card | H25: Female | I25: 3 | J25: 5 | K25: Laptop & Accessory | L25: 3 | M25: Divorced | N25: 4 | O25: 1 | P25: 11 | Q25: 1 | R25: 2 | S25: 2 | T25: 145.59
A26: 50025 | B26: 1 | C26: 14 | D26: Computer | E26: 1 | F26: 14 | G26: Debit Card | H26: Male | I26: 2 | J26: 5 | K26: Fashion | L26: 2 | M26: Single | N26: 3 | O26: 0 | P26: 15 | Q26: 0 | R26: 1 | S26: 3 | T26: 206.5
A27: 50026 | B27: 1 | C27: 0 | D27: Phone | E27: 1 | F27: 15 | G27: Credit Card | H27: Female | I27: 2 | J27: 3 | K27: Mobile Phone | L27: 5 | M27: Single | N27: 8 | O27: 0 | P27: 22 | Q27: 1 | R27: 1 | S27: 4 | T27: 142
A28: 50027 | B28: 0 | C28: 8 | D28: Mobile Phone | E28: 3 | F28: 6 | G28: E wallet | H28: Male | I28: 3 | J28: 3 | K28: Fashion | L28: 4 | M28: Divorced | N28: 2 | O28: 0 | P28: 13 | Q28: 1 | R28: 1 | S28: 6 | T28: 172.95
A29: 50028 | B29: 0 | D29: Phone | E29: 3 | F29: 12 | G29: E wallet | H29: Male | I29: 2 | J29: 3 | K29: Laptop & Accessory | L29: 3 | M29: Divorced | N29: 3 | O29: 1 | P29: 20 | Q29: 0 | R29: 4 | S29: 5 | T29: 123.06
A30: 50029 | B30: 0 | C30: 18 | D30: Phone | E30: 1 | G30: Debit Card | H30: Male | I30: 2 | J30: 3 | K30: Laptop & Accessory | L30: 4 | M30: Married | N30: 9 | O30: 0 | P30: 18 | Q30: 1 | R30: 1 | S30: 15 | T30: 123.48
A31: 50030 | B31: 0 | C31: 5 | D31: Computer | E31: 3 | F31: 14 | G31: E wallet | H31: Female | I31: 2 | J31: 3 | K31: Fashion | L31: 2 | M31: Single | N31: 2 | O31: 0 | P31: 14 | Q31: 2 | R31: 3 | S31: 7 | T31: 189.98
A32: 50031 | B32: 0 | C32: 2 | D32: Computer | E32: 1 | F32: 6 | G32: COD | H32: Male | I32: 2 | J32: 3 | K32: Laptop & Accessory | L32: 3 | M32: Divorced | N32: 2 | O32: 0 | P32: 13 | Q32: 0 | R32: 1 | S32: 9 | T32: 143.19
A33: 50032 | B33: 0 | C33: 0 | D33: Mobile Phone | E33: 1 | F33: 13 | G33: Credit Card | H33: Male | I33: 2 | J33: 4 | K33: Laptop & Accessory | L33: 3 | M33: Divorced | N33: 3 | O33: 0 | P33: 17 | Q33: 1 | R33: 1 | S33: 0 | T33: 161.32
A34: 50033 | B34: 0 | C34: 30 | D34: Phone | E34: 1 | F34: 15 | G34: CC | H34: Female | I34: 3 | J34: 4 | K34: Mobile | L34: 4 | M34: Divorced | N34: 5 | O34: 1 | P34: 20 | Q34: 1 | R34: 1 | S34: 0 | T34: 133.46
A35: 50034 | B35: 0 | C35: 13 | D35: Mobile Phone | E35: 3 | F35: 10 | G35: E wallet | H35: Male | I35: 3 | J35: 4 | K35: Fashion | L35: 2 | M35: Divorced | N35: 8 | O35: 0 | P35: 11 | Q35: 2 | R35: 2 | S35: 11 | T35: 208.55
A36: 50035 | B36: 0 | D36: Computer | E36: 3 | F36: 8 | G36: E wallet | H36: Female | I36: 3 | J36: 3 | K36: Mobile | L36: 3 | M36: Divorced | N36: 7 | O36: 0 | P36: 18 | Q36: 1 | R36: 1 | S36: 2 | T36: 122.31
A37: 50036 | B37: 0 | C37: 0 | D37: Phone | E37: 1 | G37: CC | H37: Male | I37: 3 | J37: 3 | K37: Mobile | L37: 2 | M37: Divorced | N37: 2 | O37: 0 | P37: 24 | Q37: 0 | R37: 2 | S37: 2 | T37: 123.23
A38: 50037 | B38: 0 | D38: Computer | E38: 1 | F38: 15 | G38: CC | H38: Male | I38: 2 | J38: 3 | K38: Mobile | L38: 4 | M38: Married | N38: 7 | O38: 0 | P38: 18 | Q38: 0 | R38: 2 | S38: 2 | T38: 120.24
A39: 50038 | B39: 0 | C39: 1 | D39: Phone | E39: 1 | F39: 27 | G39: CC | H39: Male | J39: 3 | K39: Mobile | L39: 2 | M39: Divorced | N39: 2 | O39: 0 | P39: 11 | Q39: 0 | R39: 1 | S39: 2 | T39: 127.13
A40: 50039 | B40: 0 | C40: 30 | D40: Mobile Phone | E40: 1 | F40: 30 | G40: Debit Card | H40: Male | I40: 2 | J40: 2 | K40: Fashion | L40: 2 | M40: Married | N40: 4 | O40: 1 | P40: 16 | Q40: 1 | R40: 1 | S40: 4 | T40: 194.39
...

Sheet Sheet1
A1: Chrun = 1 | B1: =COUNTIFS('E Comm'!B2:B5631,1) -> 948
A2: city tier 1 | B2: =COUNTIFS('E Comm'!E2:E5623,1) -> 3661
A3: city tier 2 | B3: =COUNTIFS('E Comm'!E3:E5624,2) -> 242
A4: city tier 3 | B4: =COUNTIFS('E Comm'!E4:E5625,3) -> 1719
A5: male | B5: =COUNTIFS('E Comm'!H5:H5626,"Male") -> 3377
A6: female | B6: =COUNTIFS('E Comm'!H6:H5627,"Female") -> 2245
A7: total blank cell | B7: =COUNTBLANK('E Comm'!A2:T5631) -> 1856
A8: CustomerID | B8: =COUNTBLANK('E Comm'!A2:A5631) -> 0
A9: Churn | B9: =COUNTBLANK('E Comm'!B2:B5631) -> 0
A10: Tenure | B10: =COUNTBLANK('E Comm'!C2:C5631) -> 264
A11: PreferredLoginDevice | B11: =COUNTBLANK('E Comm'!D2:D5631) -> 0
A12: CityTier | B12: =COUNTBLANK('E Comm'!E2:E5631) -> 0
A13: WarehouseToHome | B13: =COUNTBLANK('E Comm'!F2:F5631) -> 251
A14: PreferredPaymentMode | B14: =COUNTBLANK('E Comm'!G2:G5631) -> 0 | F14: =_xlfn.CONCAT(A8," ", A9," ",A11," ", A12," ", A14, " ", A15," ", A17," ", A18," ", A19," ", A20," ", A21," ", A22," ", A27) -> CustomerID Churn PreferredLoginDevice CityTier PreferredPaymentMode Gender NumberOfDeviceRegistered PreferedOrderCat SatisfactionScore MaritalStatus NumberOfAddress Complain CashbackAmount
A15: Gender | B15: =COUNTBLANK('E Comm'!H2:H5631) -> 0
A16: HourSpendOnApp | B16: =COUNTBLANK('E Comm'!I2:I5631) -> 255 | F16: =_xlfn.CONCAT(A10," ",A13," ",A16," ",A23," ",A24," ",A25," ",A26) -> Tenure WarehouseToHome HourSpendOnApp OrderAmountHikeFromlastYear CouponUsed OrderCount DaySinceLastOrder
A17: NumberOfDeviceRegistered | B17: =COUNTBLANK('E Comm'!J2:J5631) -> 0
A18: PreferedOrderCat | B18: =COUNTBLANK('E Comm'!K2:K5631) -> 0
A19: SatisfactionScore | B19: =COUNTBLANK('E Comm'!L2:L5631) -> 0
A20: MaritalStatus | B20: =COUNTBLANK('E Comm'!M2:M5631) -> 0
A21: NumberOfAddress | B21: =COUNTBLANK('E Comm'!N2:N5631) -> 0
A22: Complain | B22: =COUNTBLANK('E Comm'!O2:O5631) -> 0
A23: OrderAmountHikeFromlastYear | B23: =COUNTBLANK('E Comm'!P2:P5631) -> 265
A24: CouponUsed | B24: =COUNTBLANK('E Comm'!Q2:Q5631) -> 256
A25: OrderCount | B25: =COUNTBLANK('E Comm'!R2:R5631) -> 258
A26: DaySinceLastOrder | B26: =COUNTBLANK('E Comm'!S2:S5631) -> 307
A27: CashbackAmount | B27: =COUNTBLANK('E Comm'!T2:T5631) -> 0
